<mujoco model="a0912">
  <compiler angle="radian"/>
  <!--compiler angle="degree"-->


  <asset>
    <!-- import stl mesh files -->
    <mesh name="A0912_0_0" file="meshes/stl/A0912_0_0.stl" scale="0.001 0.001 0.001"/>
    <mesh name="A0912_1_0" file="meshes/stl/A0912_1_0.stl" scale="0.001 0.001 0.001"/>
    <mesh name="A0912_1_1" file="meshes/stl/A0912_1_1.stl" scale="0.001 0.001 0.001"/>
    <mesh name="A0912_1_2" file="meshes/stl/A0912_1_2.stl" scale="0.001 0.001 0.001"/>
    <mesh name="A0912_2_0" file="meshes/stl/A0912_2_0.stl" scale="0.001 0.001 0.001"/>
    <mesh name="A0912_2_1" file="meshes/stl/A0912_2_1.stl" scale="0.001 0.001 0.001"/>
    <mesh name="A0912_2_2" file="meshes/stl/A0912_2_2.stl" scale="0.001 0.001 0.001"/>
    <mesh name="A0912_3_0" file="meshes/stl/A0912_3_0.stl" scale="0.001 0.001 0.001"/>
    <mesh name="A0912_3_1" file="meshes/stl/A0912_3_1.stl" scale="0.001 0.001 0.001"/>
    <mesh name="A0912_4_0" file="meshes/stl/A0912_4_0.stl" scale="0.001 0.001 0.001"/>
    <mesh name="A0912_4_1" file="meshes/stl/A0912_4_1.stl" scale="0.001 0.001 0.001"/>
    <mesh name="A0912_5_0" file="meshes/stl/A0912_5_0.stl" scale="0.001 0.001 0.001"/>
    <mesh name="A0912_5_1" file="meshes/stl/A0912_5_1.stl" scale="0.001 0.001 0.001"/>
    <mesh name="A0912_6_0" file="meshes/stl/A0912_6_0.stl" scale="0.001 0.001 0.001"/>

    <!-- other assets for world -->
    <texture builtin="gradient" height="100" rgb1="1 1 1" rgb2="0 0 0" type="skybox" width="100"/>
    <texture builtin="flat" height="1278" mark="cross" markrgb="1 1 1" name="texgeom" random="0.01" rgb1="0.8 0.6 0.4" rgb2="0.8 0.6 0.4" type="cube" width="127"/>
    <texture builtin="checker" height="100" name="texplane" rgb1= "0.25 0.25 0.3" rgb2="0.4 0.4 0.45" type="2d" width="100"/>
    <material name="MatPlane" reflectance="0.3" shininess="0.5" specular="0.5" texrepeat="60 60" texture="texplane"/>
    <material name="geom" texture="texgeom" texuniform="true"/>
  </asset>



  <worldbody>
    <!-- 1. world with floor & light-->
    <light cutoff="100" diffuse="1 1 1" dir="-0 0 -1.3" directional="true" exponent="1" pos="0 0 1.3" specular=".1 .1 .1"/>
    <geom conaffinity="1" condim="3" material="MatPlane" name="floor" pos="0 0 0" rgba="0.8 0.9 0.8 1" size="40 40 40" type="plane"/>

    <!-- 1. link 0: base link, attached to ground -->
    <body name="base_0" quat="0 0 0.70710678 0.70710678">
        <geom type="mesh" mesh="A0912_0_0" rgba="0.25 0.1 0.35 1"/>

        <!-- link 1: first body -->
        <body name="link1" pos="0 0.195 0" quat="0 0 0.70710678 0.70710678">
            <inertial pos="4.4e-05 0.029982 -0.01112" quat="0.616973 0.786523 0.0212897 -0.0165244" mass="7.863" diaginertia="0.0458411 0.0451317 0.0321783"/>
            <geom type="mesh" mesh="A0912_1_0"/>
            <geom type="mesh" mesh="A0912_1_1"/>
            <geom type="mesh" mesh="A0912_1_2"/>

            <!-- joint1: vertical -->
            <joint name="joint1" pos="0 0 0" axis="0 0 1" range="-6.2832 6.2832" actuatorfrcrange="-411 411" damping="60" frictionloss="4"/>
                <body name="link2" quat="0 0.70710678 0 0.70710678">
                    <inertial pos="0.19748 0.001426 0.13191" quat="0.494865 0.500903 0.49028 0.513644" mass="10.985" diaginertia="0.676461 0.67447 0.0442288"/>
                    <joint name="joint2" pos="0 0 0" axis="0 1 0" range="-6.2832 6.2832" actuatorfrcrange="-411 411" damping="60" frictionloss="3"/>
                    <geom type="mesh" mesh="A0912_2_0"/>
                    <geom type="mesh" mesh="A0912_2_1" rgba="0.25 0.1 0.35 1"/>
                    <geom type="mesh" mesh="A0912_2_2"/>
                    <body name="link3" pos="0.56 0 0" quat="7.07106781e-01 -4.32978028e-17 7.07106781e-01 4.32978028e-17">
                        <inertial pos="8.5e-05 -0.002513 0.032058" quat="0.99956 -0.0295295 -0.00177705 -0.00235181" mass="2.881" diaginertia="0.0127561 0.0114277 0.00805338"/>
                        <joint name="joint3" pos="0 0 0" axis="0 1 0" range="-2.7925 2.7925" actuatorfrcrange="-194 194" damping="60" frictionloss="2"/>
                        <geom type="mesh" mesh="A0912_3_0"/>
                        <geom type="mesh" mesh="A0912_3_1" rgba="0.25 0.1 0.35 1"/>
                        <body name="link4" pos="0 0 0.516" quat="7.07106781e-01 7.07106781e-01 4.32978028e-17 4.32978028e-17">
                            <inertial pos="-9.6e-05 0.085314 -0.13975" quat="0.991273 -0.131746 0.000466759 0.00453423" mass="3.273" diaginertia="0.12246 0.120645 0.00961083"/>
                            <joint name="joint4" pos="0 -0.516 0" axis="0 1 0" range="-6.2832 6.2832" actuatorfrcrange="-50 50" damping="60" frictionloss="1"/>
                            <geom type="mesh" mesh="A0912_4_0" rgba="0.25 0.1 0.35 1"/>
                            <geom type="mesh" mesh="A0912_4_1"/>
                            <body name="link5" quat="7.07106781e-01 -7.07106781e-01 -4.32978028e-17 4.32978028e-17">
                                <inertial pos="0.000109 -0.003286 0.01477" quat="0.694836 0.719167 -0.00102984 0.000469357" mass="2.141" diaginertia="0.013145 0.00904965 0.00730513"/>
                                <joint name="joint5" pos="0 0 0" axis="0 1 0" range="-6.2832 6.2832" actuatorfrcrange="-50 50" damping="60" frictionloss="1"/>
                                <geom type="mesh" mesh="A0912_5_0"/>
                                <geom type="mesh" mesh="A0912_5_1" rgba="0.25 0.1 0.35 1"/>
                                <body name="link6" pos="0 0 0.12" quat="0 0 0.70710678 0.70710678">
                                    <inertial pos="-1.9e-05 -6e-06 -0.05227" quat="0.709629 0.704572 -0.0002028 0.00211458" mass="0.784" diaginertia="0.00674032 0.00596965 0.00480143"/>
                                    <joint name="joint6" pos="0 -0.12 0" axis="0 1 0" range="-6.2832 6.2832" actuatorfrcrange="-50 50" damping="60" frictionloss="1"/>
                                    <geom type="mesh" mesh="A0912_6_0"/>

                                </body>
                            </body>
                        </body>
                    </body>
                </body>
        </body>
    </body>
  </worldbody>


  <!-- actuators for joints-->
  <actuator>
    <position ctrllimited="true" ctrlrange="-1.5 1.5" joint="joint1" kp="200"/>
    <position ctrllimited="true" ctrlrange="-1.5 1.5" joint="joint2" kp="200"/>
    <position ctrllimited="true" ctrlrange="-1.5 1.5" joint="joint3" kp="200"/>
    <position ctrllimited="true" ctrlrange="-1.5 1.5" joint="joint4" kp="200"/>
    <position ctrllimited="true" ctrlrange="-1.5 1.5" joint="joint5" kp="200"/>
    <position ctrllimited="true" ctrlrange="-1.5 1.5" joint="joint6" kp="200"/>
  </actuator>


</mujoco>
